{
 "cells": [
  {
   "cell_type": "code",
   "execution_count": 7,
   "id": "b563122a",
   "metadata": {},
   "outputs": [
    {
     "ename": "SyntaxError",
     "evalue": "invalid syntax (3237484781.py, line 15)",
     "output_type": "error",
     "traceback": [
      "\u001b[1;36m  Cell \u001b[1;32mIn[7], line 15\u001b[1;36m\u001b[0m\n\u001b[1;33m    import cv2\u001b[0m\n\u001b[1;37m    ^\u001b[0m\n\u001b[1;31mSyntaxError\u001b[0m\u001b[1;31m:\u001b[0m invalid syntax\n"
     ]
    }
   ],
   "source": []
  },
  {
   "cell_type": "code",
   "execution_count": 4,
   "id": "e648919b",
   "metadata": {},
   "outputs": [
    {
     "name": "stdout",
     "output_type": "stream",
     "text": [
      "Defaulting to user installation because normal site-packages is not writeable\n",
      "Requirement already satisfied: opencv-python in c:\\users\\gayatri kulkarni\\appdata\\roaming\\python\\python311\\site-packages (4.9.0.80)\n",
      "Requirement already satisfied: numpy>=1.21.2 in c:\\programdata\\anaconda3\\lib\\site-packages (from opencv-python) (1.24.3)\n"
     ]
    }
   ],
   "source": [
    "!pip install opencv-python"
   ]
  },
  {
   "cell_type": "code",
   "execution_count": 8,
   "id": "967d5583",
   "metadata": {},
   "outputs": [
    {
     "ename": "SyntaxError",
     "evalue": "invalid syntax (3237484781.py, line 15)",
     "output_type": "error",
     "traceback": [
      "\u001b[1;36m  Cell \u001b[1;32mIn[8], line 15\u001b[1;36m\u001b[0m\n\u001b[1;33m    import cv2\u001b[0m\n\u001b[1;37m    ^\u001b[0m\n\u001b[1;31mSyntaxError\u001b[0m\u001b[1;31m:\u001b[0m invalid syntax\n"
     ]
    }
   ],
   "source": [
    "\n"
   ]
  },
  {
   "cell_type": "code",
   "execution_count": 18,
   "id": "432a32b3",
   "metadata": {},
   "outputs": [
    {
     "ename": "ModuleNotFoundError",
     "evalue": "No module named 'face_recognition'",
     "output_type": "error",
     "traceback": [
      "\u001b[1;31m---------------------------------------------------------------------------\u001b[0m",
      "\u001b[1;31mModuleNotFoundError\u001b[0m                       Traceback (most recent call last)",
      "Cell \u001b[1;32mIn[18], line 1\u001b[0m\n\u001b[1;32m----> 1\u001b[0m \u001b[38;5;28;01mimport\u001b[39;00m \u001b[38;5;21;01mface_recognition\u001b[39;00m\n\u001b[0;32m      2\u001b[0m \u001b[38;5;28;01mfrom\u001b[39;00m \u001b[38;5;21;01mmatplotlib\u001b[39;00m\u001b[38;5;21;01m.\u001b[39;00m\u001b[38;5;21;01mpatches\u001b[39;00m \u001b[38;5;28;01mimport\u001b[39;00m Rectangle \n\u001b[0;32m      3\u001b[0m \u001b[38;5;28;01mimport\u001b[39;00m \u001b[38;5;21;01mmatplotlib\u001b[39;00m\u001b[38;5;21;01m.\u001b[39;00m\u001b[38;5;21;01mpyplot\u001b[39;00m \u001b[38;5;28;01mas\u001b[39;00m \u001b[38;5;21;01mplt\u001b[39;00m\n",
      "\u001b[1;31mModuleNotFoundError\u001b[0m: No module named 'face_recognition'"
     ]
    }
   ],
   "source": [
    "import face_recognition\n",
    "from matplotlib.patches import Rectangle \n",
    "import matplotlib.pyplot as plt\n",
    "\n",
    "#Load a sample picture and Learn how to recognize it.\n",
    "known_image = face_recognition.load_image_file(\"gayatri.jpg\") #Replace with your known image path\n",
    "known_face_encoding = face_recognition.face_encodings(known_image) (0)\n",
    "\n",
    "#Load an unknown indge to recognize faces in\n",
    "unknown_image = face_recognition.load_image_file(\"Image1.jpg\") #Replace with your unknown image path\n",
    "unknown_face_locations = face_recognition.face_locations(unknown_image)  \n",
    "unknown_face_encodings = face_recognition.face_encodings(unknown_image, unknown_face_locations)\n",
    "\n",
    "#Convert the image to RGB (natplotlib expects RGB format)\n",
    "unknown_image_rgb = unknown_image[:, :, ::,-1]\n",
    "\n",
    "#Create a subplot\n",
    "fig, ax = plt.subplots(figsize=(8, 6))\n",
    "ax.imshow(unknown_image_rgb)\n",
    "\n",
    "#Loop through each face found in the unknown (mage\n",
    "\n",
    "for (top, right, bottom, left), unknown_face_encoding in zip(unknown_face_locations, unknown_face_encodings):\n",
    "#See if the face is a match for the known face(s) \n",
    "    results = face_recognition.compare_faces((known_face_encoding), unknown_face_encoding)\n",
    "    if results[0]:\n",
    "        name = \"Known-Rajesh\"\n",
    "    else:\n",
    "        name = \"Unknown\"\n",
    "   # Draw a box around the face\n",
    "    ax.add_path(Rectangle((left, top), right - left, bottom - top,\n",
    "                        fill=False, color='green', linewidth=2))\n",
    "    ax.text(left + 6, bottom + 25, name, color='white', fontsize=12)\n",
    "# Display the results\n",
    "plt.axis('off') #Hide the axis\n",
    "plt.show()"
   ]
  },
  {
   "cell_type": "code",
   "execution_count": 19,
   "id": "9de46fa1",
   "metadata": {},
   "outputs": [
    {
     "name": "stdout",
     "output_type": "stream",
     "text": [
      "Defaulting to user installation because normal site-packages is not writeable\n",
      "Collecting face_recognition\n",
      "  Obtaining dependency information for face_recognition from https://files.pythonhosted.org/packages/1e/95/f6c9330f54ab07bfa032bf3715c12455a381083125d8880c43cbe76bb3d0/face_recognition-1.3.0-py2.py3-none-any.whl.metadata\n",
      "  Downloading face_recognition-1.3.0-py2.py3-none-any.whl.metadata (21 kB)\n",
      "Collecting face-recognition-models>=0.3.0 (from face_recognition)\n",
      "  Using cached face_recognition_models-0.3.0.tar.gz (100.1 MB)\n",
      "  Preparing metadata (setup.py): started\n",
      "  Preparing metadata (setup.py): finished with status 'done'\n",
      "Requirement already satisfied: Click>=6.0 in c:\\programdata\\anaconda3\\lib\\site-packages (from face_recognition) (8.0.4)\n",
      "Collecting dlib>=19.7 (from face_recognition)\n",
      "  Using cached dlib-19.24.4.tar.gz (3.3 MB)\n",
      "  Installing build dependencies: started\n",
      "  Installing build dependencies: finished with status 'done'\n",
      "  Getting requirements to build wheel: started\n",
      "  Getting requirements to build wheel: finished with status 'done'\n",
      "  Preparing metadata (pyproject.toml): started\n",
      "  Preparing metadata (pyproject.toml): finished with status 'done'\n",
      "Requirement already satisfied: numpy in c:\\programdata\\anaconda3\\lib\\site-packages (from face_recognition) (1.24.3)\n",
      "Requirement already satisfied: Pillow in c:\\programdata\\anaconda3\\lib\\site-packages (from face_recognition) (9.4.0)\n",
      "Requirement already satisfied: colorama in c:\\programdata\\anaconda3\\lib\\site-packages (from Click>=6.0->face_recognition) (0.4.6)\n",
      "Using cached face_recognition-1.3.0-py2.py3-none-any.whl (15 kB)\n",
      "Building wheels for collected packages: dlib, face-recognition-models\n",
      "  Building wheel for dlib (pyproject.toml): started\n",
      "  Building wheel for dlib (pyproject.toml): finished with status 'error'\n",
      "  Building wheel for face-recognition-models (setup.py): started\n",
      "  Building wheel for face-recognition-models (setup.py): finished with status 'done'\n",
      "  Created wheel for face-recognition-models: filename=face_recognition_models-0.3.0-py2.py3-none-any.whl size=100566184 sha256=eb35c8a626db37b88f45b37821b5b3c1be2c87fa6b10ac1a9b421cd8794690a2\n",
      "  Stored in directory: c:\\users\\gayatri kulkarni\\appdata\\local\\pip\\cache\\wheels\\04\\52\\ec\\9355da79c29f160b038a20c784db2803c2f9fa2c8a462c176a\n",
      "Successfully built face-recognition-models\n",
      "Failed to build dlib\n"
     ]
    },
    {
     "name": "stderr",
     "output_type": "stream",
     "text": [
      "  error: subprocess-exited-with-error\n",
      "  \n",
      "  Building wheel for dlib (pyproject.toml) did not run successfully.\n",
      "  exit code: 1\n",
      "  \n",
      "  [6 lines of output]\n",
      "  running bdist_wheel\n",
      "  running build\n",
      "  running build_ext\n",
      "  \n",
      "  ERROR: CMake must be installed to build dlib\n",
      "  \n",
      "  [end of output]\n",
      "  \n",
      "  note: This error originates from a subprocess, and is likely not a problem with pip.\n",
      "  ERROR: Failed building wheel for dlib\n",
      "ERROR: Could not build wheels for dlib, which is required to install pyproject.toml-based projects\n"
     ]
    }
   ],
   "source": [
    "!pip install face_recognition"
   ]
  },
  {
   "cell_type": "code",
   "execution_count": null,
   "id": "ec656f0d",
   "metadata": {},
   "outputs": [],
   "source": []
  }
 ],
 "metadata": {
  "kernelspec": {
   "display_name": "Python 3 (ipykernel)",
   "language": "python",
   "name": "python3"
  },
  "language_info": {
   "codemirror_mode": {
    "name": "ipython",
    "version": 3
   },
   "file_extension": ".py",
   "mimetype": "text/x-python",
   "name": "python",
   "nbconvert_exporter": "python",
   "pygments_lexer": "ipython3",
   "version": "3.11.5"
  }
 },
 "nbformat": 4,
 "nbformat_minor": 5
}
